Workbook
Name Slicer_Age_Group1: #N/A
Name Slicer_Credit_Categorical: #N/A
Name Slicer_DTI_RISK_LEVEL: #N/A
Name Slicer_Education_Level: #N/A
Name Slicer_Employment_Status: #N/A
Name Slicer_Gender: #N/A
Name Slicer_Has_Existing_Loan: #N/A
Name Slicer_Loan_Approved: #N/A

Sheet Data Works
A1: Applicant_ID | B1: Applicant_Income | C1: Coapplicant_Income | D1: Total_Income | E1: Employment_Status | F1: Age | G1: Age_Group | H1: Marital_Status | I1: Dependents | J1: Dependents Group | K1: Credit_Score | L1: Credit Categorical | M1: Existing_Loans | N1: Has_Existing_Loan | O1: DTI_Ratio | P1: DTI RISK LEVEL | Q1: Savings | R1: Collateral_Value | S1: Has Collateral | T1: Loan_Amount | U1: Loan Size | V1: Loan_Term | W1: Loan_Term_Year | X1: Loan_Purpose | Y1: Property_Area | Z1: Education_Level | AA1: Gender | AB1: Employer_Category | AC1: Loan_Approved
A2: 1 | B2: 17795 | C2: 1387 | D2: =B2+C2 -> 19182 | E2: Salaried | F2: 51 | G2: {=_xlfn.IFS(F2<25,"18-24",F2<35,"25-35",F2<45,"35-44",F2<55,"44-54",F2>=55,"55+")} -> 44-54 | H2: Married | I2: 0 | J2: {=_xlfn.IFS(I2<=0,"No Dependents",I2<=1,"One",I2<=2,"Two",I2>=3,"Third")} -> No Dependents | K2: 637 | L2: {=_xlfn.IFS(K2<=580,"Poor",K2<=670,"fair",K2<=740,"Good",K2<=800,"Very Good",K2>=800,"Excellent")} -> fair | M2: 4 | N2: =IF(M2>0,"Yes","No") -> Yes | O2: 0.53 | P2: {=_xlfn.IFS(O2<=0.3,"Low Risk",O2<=0.4,"medium Risk",O2<=0.5,"High Risk",O2>0.5,"Very High Risk")} -> Very High Risk | Q2: 19403 | R2: 45638 | S2: =IF(R2>100,"Yes","No") -> Yes | T2: 16619 | U2: {=_xlfn.IFS(T2<5000,"Small",T2<20000,"Medium",T2<35000,"Large",T2>35000,"Very Large")} -> Medium | V2: 84 | W2: =V2/12 -> 7 | X2: Personal | Y2: Urban | Z2: Not Graduate | AA2: Female | AB2: Private | AC2: No
A3: 2 | B3: 2860 | C3: 2679 | D3: =B3+C3 -> 5539 | E3: Salaried | F3: 46 | G3: {=_xlfn.IFS(F3<25,"18-24",F3<35,"25-35",F3<45,"35-44",F3<55,"44-54",F3>=55,"55+")} -> 44-54 | H3: Married | I3: 3 | J3: {=_xlfn.IFS(I3<=0,"No Dependents",I3<=1,"One",I3<=2,"Two",I3>=3,"Third")} -> Third | K3: 621 | L3: {=_xlfn.IFS(K3<=580,"Poor",K3<=670,"fair",K3<=740,"Good",K3<=800,"Very Good",K3>=800,"Excellent")} -> fair | M3: 2 | N3: =IF(M3>0,"Yes","No") -> Yes | O3: 0.3 | P3: {=_xlfn.IFS(O3<=0.3,"Low Risk",O3<=0.4,"medium Risk",O3<=0.5,"High Risk",O3>0.5,"Very High Risk")} -> Low Risk | Q3: 2580 | R3: 49272 | S3: =IF(R3>100,"Yes","No") -> Yes | T3: 38687 | U3: {=_xlfn.IFS(T3<5000,"Small",T3<20000,"Medium",T3<35000,"Large",T3>35000,"Very Large")} -> Very Large | V3: 48 | W3: =V3/12 -> 4 | X3: Car | Y3: Semiurban | Z3: Graduate | AA3: Male | AB3: Private | AC3: No
A4: 3 | B4: 7390 | C4: 2106 | D4: =B4+C4 -> 9496 | E4: Salaried | F4: 25 | G4: {=_xlfn.IFS(F4<25,"18-24",F4<35,"25-35",F4<45,"35-44",F4<55,"44-54",F4>=55,"55+")} -> 25-35 | H4: Single | I4: 2 | J4: {=_xlfn.IFS(I4<=0,"No Dependents",I4<=1,"One",I4<=2,"Two",I4>=3,"Third")} -> Two | K4: 674 | L4: {=_xlfn.IFS(K4<=580,"Poor",K4<=670,"fair",K4<=740,"Good",K4<=800,"Very Good",K4>=800,"Excellent")} -> Good | M4: 4 | N4: =IF(M4>0,"Yes","No") -> Yes | O4: 0.2 | P4: {=_xlfn.IFS(O4<=0.3,"Low Risk",O4<=0.4,"medium Risk",O4<=0.5,"High Risk",O4>0.5,"Very High Risk")} -> Low Risk | Q4: 13844 | R4: 6908 | S4: =IF(R4>100,"Yes","No") -> Yes | T4: 27943 | U4: {=_xlfn.IFS(T4<5000,"Small",T4<20000,"Medium",T4<35000,"Large",T4>35000,"Very Large")} -> Large | V4: 72 | W4: =V4/12 -> 6 | X4: Business | Y4: Urban | Z4: Graduate | AA4: Female | AB4: Government | AC4: Yes
A5: 4 | B5: 13964 | C5: 8173 | D5: =B5+C5 -> 22137 | E5: Salaried | F5: 40 | G5: {=_xlfn.IFS(F5<25,"18-24",F5<35,"25-35",F5<45,"35-44",F5<55,"44-54",F5>=55,"55+")} -> 35-44 | H5: Married | I5: 2 | J5: {=_xlfn.IFS(I5<=0,"No Dependents",I5<=1,"One",I5<=2,"Two",I5>=3,"Third")} -> Two | K5: 579 | L5: {=_xlfn.IFS(K5<=580,"Poor",K5<=670,"fair",K5<=740,"Good",K5<=800,"Very Good",K5>=800,"Excellent")} -> Poor | M5: 3 | N5: =IF(M5>0,"Yes","No") -> Yes | O5: 0.31 | P5: {=_xlfn.IFS(O5<=0.3,"Low Risk",O5<=0.4,"medium Risk",O5<=0.5,"High Risk",O5>0.5,"Very High Risk")} -> medium Risk | Q5: 9553 | R5: 10844 | S5: =IF(R5>100,"Yes","No") -> Yes | T5: 27819 | U5: {=_xlfn.IFS(T5<5000,"Small",T5<20000,"Medium",T5<35000,"Large",T5>35000,"Very Large")} -> Large | V5: 60 | W5: =V5/12 -> 5 | X5: Business | Y5: Rural | Z5: Graduate | AA5: Female | AB5: Government | AC5: No
A6: 5 | B6: 13284 | C6: 4223 | D6: =B6+C6 -> 17507 | E6: Self-employed | F6: 31 | G6: {=_xlfn.IFS(F6<25,"18-24",F6<35,"25-35",F6<45,"35-44",F6<55,"44-54",F6>=55,"55+")} -> 25-35 | H6: Single | I6: 2 | J6: {=_xlfn.IFS(I6<=0,"No Dependents",I6<=1,"One",I6<=2,"Two",I6>=3,"Third")} -> Two | K6: 721 | L6: {=_xlfn.IFS(K6<=580,"Poor",K6<=670,"fair",K6<=740,"Good",K6<=800,"Very Good",K6>=800,"Excellent")} -> Good | M6: 1 | N6: =IF(M6>0,"Yes","No") -> Yes | O6: 0.29 | P6: {=_xlfn.IFS(O6<=0.3,"Low Risk",O6<=0.4,"medium Risk",O6<=0.5,"High Risk",O6>0.5,"Very High Risk")} -> Low Risk | Q6: 9386 | R6: 37629 | S6: =IF(R6>100,"Yes","No") -> Yes | T6: 12741 | U6: {=_xlfn.IFS(T6<5000,"Small",T6<20000,"Medium",T6<35000,"Large",T6>35000,"Very Large")} -> Medium | V6: 72 | W6: =V6/12 -> 6 | X6: Car | Y6: Urban | Z6: Graduate | AA6: Male | AB6: Private | AC6: Yes
A7: 6 | B7: 8265 | C7: 4831 | D7: =B7+C7 -> 13096 | E7: Salaried | F7: 53 | G7: {=_xlfn.IFS(F7<25,"18-24",F7<35,"25-35",F7<45,"35-44",F7<55,"44-54",F7>=55,"55+")} -> 44-54 | H7: Single | I7: 1 | J7: {=_xlfn.IFS(I7<=0,"No Dependents",I7<=1,"One",I7<=2,"Two",I7>=3,"Third")} -> One | K7: 602 | L7: {=_xlfn.IFS(K7<=580,"Poor",K7<=670,"fair",K7<=740,"Good",K7<=800,"Very Good",K7>=800,"Excellent")} -> fair | M7: 1 | N7: =IF(M7>0,"Yes","No") -> Yes | O7: 0.56 | P7: {=_xlfn.IFS(O7<=0.3,"Low Risk",O7<=0.4,"medium Risk",O7<=0.5,"High Risk",O7>0.5,"Very High Risk")} -> Very High Risk | Q7: 19522 | R7: 2911 | S7: =IF(R7>100,"Yes","No") -> Yes | T7: 9798 | U7: {=_xlfn.IFS(T7<5000,"Small",T7<20000,"Medium",T7<35000,"Large",T7>35000,"Very Large")} -> Medium | V7: 36 | W7: =V7/12 -> 3 | X7: Home | Y7: Semiurban | Z7: Graduate | AA7: Male | AB7: Unemployed | AC7: No
A8: 7 | B8: 18850 | C8: 2768 | D8: =B8+C8 -> 21618 | E8: Salaried | F8: 58 | G8: {=_xlfn.IFS(F8<25,"18-24",F8<35,"25-35",F8<45,"35-44",F8<55,"44-54",F8>=55,"55+")} -> 55+ | H8: Married | I8: 0 | J8: {=_xlfn.IFS(I8<=0,"No Dependents",I8<=1,"One",I8<=2,"Two",I8>=3,"Third")} -> No Dependents | K8: 687 | L8: {=_xlfn.IFS(K8<=580,"Poor",K8<=670,"fair",K8<=740,"Good",K8<=800,"Very Good",K8>=800,"Excellent")} -> Good | M8: 0 | N8: =IF(M8>0,"Yes","No") -> No | O8: 0.48 | P8: {=_xlfn.IFS(O8<=0.3,"Low Risk",O8<=0.4,"medium Risk",O8<=0.5,"High Risk",O8>0.5,"Very High Risk")} -> High Risk | Q8: 14635 | R8: 8991 | S8: =IF(R8>100,"Yes","No") -> Yes | T8: 26143 | U8: {=_xlfn.IFS(T8<5000,"Small",T8<20000,"Medium",T8<35000,"Large",T8>35000,"Very Large")} -> Large | V8: 24 | W8: =V8/12 -> 2 | X8: Home | Y8: Rural | Z8: Graduate | AA8: Male | AB8: Private | AC8: No
A9: 8 | B9: 6426 | C9: 3186 | D9: =B9+C9 -> 9612 | E9: Salaried | F9: 47 | G9: {=_xlfn.IFS(F9<25,"18-24",F9<35,"25-35",F9<45,"35-44",F9<55,"44-54",F9>=55,"55+")} -> 44-54 | H9: Married | I9: 2 | J9: {=_xlfn.IFS(I9<=0,"No Dependents",I9<=1,"One",I9<=2,"Two",I9>=3,"Third")} -> Two | K9: 636 | L9: {=_xlfn.IFS(K9<=580,"Poor",K9<=670,"fair",K9<=740,"Good",K9<=800,"Very Good",K9>=800,"Excellent")} -> fair | M9: 4 | N9: =IF(M9>0,"Yes","No") -> Yes | O9: 0.35 | P9: {=_xlfn.IFS(O9<=0.3,"Low Risk",O9<=0.4,"medium Risk",O9<=0.5,"High Risk",O9>0.5,"Very High Risk")} -> medium Risk | Q9: 671 | R9: 11572 | S9: =IF(R9>100,"Yes","No") -> Yes | T9: 33747 | U9: {=_xlfn.IFS(T9<5000,"Small",T9<20000,"Medium",T9<35000,"Large",T9>35000,"Very Large")} -> Large | V9: 84 | W9: =V9/12 -> 7 | X9: Personal | Y9: Rural | Z9: Graduate | AA9: Female | AB9: Private | AC9: No
A10: 9 | B10: 16423 | C10: 0 | D10: =B10+C10 -> 16423 | E10: Salaried | F10: 54 | G10: {=_xlfn.IFS(F10<25,"18-24",F10<35,"25-35",F10<45,"35-44",F10<55,"44-54",F10>=55,"55+")} -> 44-54 | H10: Married | I10: 1 | J10: {=_xlfn.IFS(I10<=0,"No Dependents",I10<=1,"One",I10<=2,"Two",I10>=3,"Third")} -> One | K10: 729 | L10: {=_xlfn.IFS(K10<=580,"Poor",K10<=670,"fair",K10<=740,"Good",K10<=800,"Very Good",K10>=800,"Excellent")} -> Good | M10: 0 | N10: =IF(M10>0,"Yes","No") -> No | O10: 0.59 | P10: {=_xlfn.IFS(O10<=0.3,"Low Risk",O10<=0.4,"medium Risk",O10<=0.5,"High Risk",O10>0.5,"Very High Risk")} -> Very High Risk | Q10: 777 | R10: 43066 | S10: =IF(R10>100,"Yes","No") -> Yes | T10: 34651 | U10: {=_xlfn.IFS(T10<5000,"Small",T10<20000,"Medium",T10<35000,"Large",T10>35000,"Very Large")} -> Large | V10: 36 | W10: =V10/12 -> 3 | X10: Home | Y10: Semiurban | Z10: Graduate | AA10: Male | AB10: Private | AC10: No
A11: 10 | B11: 13363 | C11: 2599 | D11: =B11+C11 -> 15962 | E11: Contract | F11: 35 | G11: {=_xlfn.IFS(F11<25,"18-24",F11<35,"25-35",F11<45,"35-44",F11<55,"44-54",F11>=55,"55+")} -> 35-44 | H11: Single | I11: 3 | J11: {=_xlfn.IFS(I11<=0,"No Dependents",I11<=1,"One",I11<=2,"Two",I11>=3,"Third")} -> Third | K11: 726 | L11: {=_xlfn.IFS(K11<=580,"Poor",K11<=670,"fair",K11<=740,"Good",K11<=800,"Very Good",K11>=800,"Excellent")} -> Good | M11: 1 | N11: =IF(M11>0,"Yes","No") -> Yes | O11: 0.35 | P11: {=_xlfn.IFS(O11<=0.3,"Low Risk",O11<=0.4,"medium Risk",O11<=0.5,"High Risk",O11>0.5,"Very High Risk")} -> medium Risk | Q11: 3022 | R11: 29693 | S11: =IF(R11>100,"Yes","No") -> Yes | T11: 22182 | U11: {=_xlfn.IFS(T11<5000,"Small",T11<20000,"Medium",T11<35000,"Large",T11>35000,"Very Large")} -> Large | V11: 60 | W11: =V11/12 -> 5 | X11: Personal | Y11: Rural | Z11: Graduate | AA11: Female | AB11: Government | AC11: Yes
A12: 11 | B12: 18023 | C12: 4033 | D12: =B12+C12 -> 22056 | E12: Salaried | F12: 52 | G12: {=_xlfn.IFS(F12<25,"18-24",F12<35,"25-35",F12<45,"35-44",F12<55,"44-54",F12>=55,"55+")} -> 44-54 | H12: Married | I12: 2 | J12: {=_xlfn.IFS(I12<=0,"No Dependents",I12<=1,"One",I12<=2,"Two",I12>=3,"Third")} -> Two | K12: 688 | L12: {=_xlfn.IFS(K12<=580,"Poor",K12<=670,"fair",K12<=740,"Good",K12<=800,"Very Good",K12>=800,"Excellent")} -> Good | M12: 1 | N12: =IF(M12>0,"Yes","No") -> Yes | O12: 0.13 | P12: {=_xlfn.IFS(O12<=0.3,"Low Risk",O12<=0.4,"medium Risk",O12<=0.5,"High Risk",O12>0.5,"Very High Risk")} -> Low Risk | Q12: 18244 | R12: 40004 | S12: =IF(R12>100,"Yes","No") -> Yes | T12: 10415 | U12: {=_xlfn.IFS(T12<5000,"Small",T12<20000,"Medium",T12<35000,"Large",T12>35000,"Very Large")} -> Medium | V12: 12 | W12: =V12/12 -> 1 | X12: Education | Y12: Urban | Z12: Not Graduate | AA12: Female | AB12: MNC | AC12: Yes
A13: 12 | B13: 10322 | C13: 8428 | D13: =B13+C13 -> 18750 | E13: Self-employed | F13: 41 | G13: {=_xlfn.IFS(F13<25,"18-24",F13<35,"25-35",F13<45,"35-44",F13<55,"44-54",F13>=55,"55+")} -> 35-44 | H13: Married | I13: 1 | J13: {=_xlfn.IFS(I13<=0,"No Dependents",I13<=1,"One",I13<=2,"Two",I13>=3,"Third")} -> One | K13: 743 | L13: {=_xlfn.IFS(K13<=580,"Poor",K13<=670,"fair",K13<=740,"Good",K13<=800,"Very Good",K13>=800,"Excellent")} -> Very Good | M13: 4 | N13: =IF(M13>0,"Yes","No") -> Yes | O13: 0.23 | P13: {=_xlfn.IFS(O13<=0.3,"Low Risk",O13<=0.4,"medium Risk",O13<=0.5,"High Risk",O13>0.5,"Very High Risk")} -> Low Risk | Q13: 0 | R13: 38333 | S13: =IF(R13>100,"Yes","No") -> Yes | T13: 12085 | U13: {=_xlfn.IFS(T13<5000,"Small",T13<20000,"Medium",T13<35000,"Large",T13>35000,"Very Large")} -> Medium | V13: 84 | W13: =V13/12 -> 7 | X13: Car | Y13: Semiurban | Z13: Graduate | AA13: Male | AB13: Government | AC13: Yes
... A951: 1000 | B951: 13093 | C951: 2385 | D951: =B951+C951 -> 15478 | E951: Salaried | F951: 23 | G951: {=_xlfn.IFS(F951<25,"18-24",F951<35,"25-35",F951<45,"35-44",F951<55,"44-54",F951>=55,"55+")} -> 18-24 | H951: Married | I951: 1 | J951: {=_xlfn.IFS(I951<=0,"No Dependents",I951<=1,"One",I951<=2,"Two",I951>=3,"Third")} -> One | K951: 613 | L951: {=_xlfn.IFS(K951<=580,"Poor",K951<=670,"fair",K951<=740,"Good",K951<=800,"Very Good",K951>=800,"Excellent")} -> fair | M951: 3 | N951: =IF(M951>0,"Yes","No") -> Yes | O951: 0.32 | P951: {=_xlfn.IFS(O951<=0.3,"Low Risk",O951<=0.4,"medium Risk",O951<=0.5,"High Risk",O951>0.5,"Very High Risk")} -> medium Risk | Q951: 12436 | R951: 25816 | S951: =IF(R951>100,"Yes","No") -> Yes | T951: 35818 | U951: {=_xlfn.IFS(T951<5000,"Small",T951<20000,"Medium",T951<35000,"Large",T951>35000,"Very Large")} -> Very Large | V951: 48 | W951: =V951/12 -> 4 | X951: Personal | Y951: Semiurban | Z951: Graduate | AA951: Male | AB951: Private | AC951: No

Sheet Clean Data
A1: Applicant_ID | B1: Applicant_Income | C1: Coapplicant_Income | D1: Total_Income | E1: Employment_Status | F1: Age | G1: Age_Group | H1: Marital_Status | I1: Dependents | J1: Dependents Group | K1: Credit_Score | L1: Credit Categorical | M1: Existing_Loans | N1: Has_Existing_Loan | O1: DTI_Ratio | P1: DTI RISK LEVEL | Q1: Savings | R1: Collateral_Value | S1: Has Collateral | T1: Loan_Amount | U1: Loan Size | V1: Loan_Term | W1: Loan_Term_Year | X1: Loan_Purpose | Y1: Property_Area | Z1: Education_Level | AA1: Gender | AB1: Employer_Category | AC1: Loan_Approved
A2: 1 | B2: 17795 | C2: 1387 | D2: 19182 | E2: Salaried | F2: 51 | G2: 44-54 | H2: Married | I2: 0 | J2: No Dependents | K2: 637 | L2: fair | M2: 4 | N2: Yes | O2: 0.53 | P2: Very High Risk | Q2: 19403 | R2: 45638 | S2: Yes | T2: 16619 | U2: Medium | V2: 84 | W2: 7 | X2: Personal | Y2: Urban | Z2: Not Graduate | AA2: Female | AB2: Private | AC2: No
A3: 2 | B3: 2860 | C3: 2679 | D3: 5539 | E3: Salaried | F3: 46 | G3: 44-54 | H3: Married | I3: 3 | J3: Third | K3: 621 | L3: fair | M3: 2 | N3: Yes | O3: 0.3 | P3: Low Risk | Q3: 2580 | R3: 49272 | S3: Yes | T3: 38687 | U3: Very Large | V3: 48 | W3: 4 | X3: Car | Y3: Semiurban | Z3: Graduate | AA3: Male | AB3: Private | AC3: No
A4: 3 | B4: 7390 | C4: 2106 | D4: 9496 | E4: Salaried | F4: 25 | G4: 25-35 | H4: Single | I4: 2 | J4: Two | K4: 674 | L4: Good | M4: 4 | N4: Yes | O4: 0.2 | P4: Low Risk | Q4: 13844 | R4: 6908 | S4: Yes | T4: 27943 | U4: Large | V4: 72 | W4: 6 | X4: Business | Y4: Urban | Z4: Graduate | AA4: Female | AB4: Government | AC4: Yes
A5: 4 | B5: 13964 | C5: 8173 | D5: 22137 | E5: Salaried | F5: 40 | G5: 35-44 | H5: Married | I5: 2 | J5: Two | K5: 579 | L5: Poor | M5: 3 | N5: Yes | O5: 0.31 | P5: medium Risk | Q5: 9553 | R5: 10844 | S5: Yes | T5: 27819 | U5: Large | V5: 60 | W5: 5 | X5: Business | Y5: Rural | Z5: Graduate | AA5: Female | AB5: Government | AC5: No
A6: 5 | B6: 13284 | C6: 4223 | D6: 17507 | E6: Self-employed | F6: 31 | G6: 25-35 | H6: Single | I6: 2 | J6: Two | K6: 721 | L6: Good | M6: 1 | N6: Yes | O6: 0.29 | P6: Low Risk | Q6: 9386 | R6: 37629 | S6: Yes | T6: 12741 | U6: Medium | V6: 72 | W6: 6 | X6: Car | Y6: Urban | Z6: Graduate | AA6: Male | AB6: Private | AC6: Yes
A7: 6 | B7: 8265 | C7: 4831 | D7: 13096 | E7: Salaried | F7: 53 | G7: 44-54 | H7: Single | I7: 1 | J7: One | K7: 602 | L7: fair | M7: 1 | N7: Yes | O7: 0.56 | P7: Very High Risk | Q7: 19522 | R7: 2911 | S7: Yes | T7: 9798 | U7: Medium | V7: 36 | W7: 3 | X7: Home | Y7: Semiurban | Z7: Graduate | AA7: Male | AB7: Unemployed | AC7: No
A8: 7 | B8: 18850 | C8: 2768 | D8: 21618 | E8: Salaried | F8: 58 | G8: 55+ | H8: Married | I8: 0 | J8: No Dependents | K8: 687 | L8: Good | M8: 0 | N8: No | O8: 0.48 | P8: High Risk | Q8: 14635 | R8: 8991 | S8: Yes | T8: 26143 | U8: Large | V8: 24 | W8: 2 | X8: Home | Y8: Rural | Z8: Graduate | AA8: Male | AB8: Private | AC8: No
A9: 8 | B9: 6426 | C9: 3186 | D9: 9612 | E9: Salaried | F9: 47 | G9: 44-54 | H9: Married | I9: 2 | J9: Two | K9: 636 | L9: fair | M9: 4 | N9: Yes | O9: 0.35 | P9: medium Risk | Q9: 671 | R9: 11572 | S9: Yes | T9: 33747 | U9: Large | V9: 84 | W9: 7 | X9: Personal | Y9: Rural | Z9: Graduate | AA9: Female | AB9: Private | AC9: No
A10: 9 | B10: 16423 | C10: 0 | D10: 16423 | E10: Salaried | F10: 54 | G10: 44-54 | H10: Married | I10: 1 | J10: One | K10: 729 | L10: Good | M10: 0 | N10: No | O10: 0.59 | P10: Very High Risk | Q10: 777 | R10: 43066 | S10: Yes | T10: 34651 | U10: Large | V10: 36 | W10: 3 | X10: Home | Y10: Semiurban | Z10: Graduate | AA10: Male | AB10: Private | AC10: No
A11: 10 | B11: 13363 | C11: 2599 | D11: 15962 | E11: Contract | F11: 35 | G11: 35-44 | H11: Single | I11: 3 | J11: Third | K11: 726 | L11: Good | M11: 1 | N11: Yes | O11: 0.35 | P11: medium Risk | Q11: 3022 | R11: 29693 | S11: Yes | T11: 22182 | U11: Large | V11: 60 | W11: 5 | X11: Personal | Y11: Rural | Z11: Graduate | AA11: Female | AB11: Government | AC11: Yes
A12: 11 | B12: 18023 | C12: 4033 | D12: 22056 | E12: Salaried | F12: 52 | G12: 44-54 | H12: Married | I12: 2 | J12: Two | K12: 688 | L12: Good | M12: 1 | N12: Yes | O12: 0.13 | P12: Low Risk | Q12: 18244 | R12: 40004 | S12: Yes | T12: 10415 | U12: Medium | V12: 12 | W12: 1 | X12: Education | Y12: Urban | Z12: Not Graduate | AA12: Female | AB12: MNC | AC12: Yes
A13: 12 | B13: 10322 | C13: 8428 | D13: 18750 | E13: Self-employed | F13: 41 | G13: 35-44 | H13: Married | I13: 1 | J13: One | K13: 743 | L13: Very Good | M13: 4 | N13: Yes | O13: 0.23 | P13: Low Risk | Q13: 0 | R13: 38333 | S13: Yes | T13: 12085 | U13: Medium | V13: 84 | W13: 7 | X13: Car | Y13: Semiurban | Z13: Graduate | AA13: Male | AB13: Government | AC13: Yes
... A951: 1000 | B951: 13093 | C951: 2385 | D951: 15478 | E951: Salaried | F951: 23 | G951: 18-24 | H951: Married | I951: 1 | J951: One | K951: 613 | L951: fair | M951: 3 | N951: Yes | O951: 0.32 | P951: medium Risk | Q951: 12436 | R951: 25816 | S951: Yes | T951: 35818 | U951: Very Large | V951: 48 | W951: 4 | X951: Personal | Y951: Semiurban | Z951: Graduate | AA951: Male | AB951: Private | AC951: No

Sheet Pivot table
A1: KPI Q1- Total Applications
B3: Count of Applicant_ID
B4: 950
A7: KPI Q2- Q3 Total Approved Loans Vs Total Rejected Loans.
B9: Row Labels | C9: Count of Loan_Approved
B10: No | C10: 664 | F10: =GETPIVOTDATA("Loan_Approved",$B$9,"Loan_Approved","No") -> 664
B11: Yes | C11: 286 | F11: =GETPIVOTDATA("Loan_Approved",$B$9,"Loan_Approved","Yes") -> 286
B12: Grand Total | C12: 950
A15: KPI Q4- Approved Rate(%)
C18: =GETPIVOTDATA("Loan_Approved",$B$9,"Loan_Approved","Yes")/GETPIVOTDATA("Loan_Approved",$B$9) -> 0.30105263 | D18: =GETPIVOTDATA("Loan_Approved",$B$9)/950 -> 1
A21: KPI Q5- Rejection Rate (%)
C24: =GETPIVOTDATA("Loan_Approved",$B$9,"Loan_Approved","No")/GETPIVOTDATA("Loan_Approved",$B$9) -> 0.69894737
A28: KPI Q6- Total loan Amount Applied
B31: Sum of Loan_Amount
B32: 18455015 | C32: =GETPIVOTDATA("Loan_Amount",$B$31) -> 18455015
A36: KPI Q7- Total Loan Amount Approved
B39: Row Labels | C39: Sum of Loan_Amount
B40: No | C40: 13529011 | E40: =GETPIVOTDATA("Loan_Amount",$B$39,"Loan_Approved","No") -> 13529011
B41: Yes | C41: 4926004 | E41: =GETPIVOTDATA("Loan_Amount",$B$39,"Loan_Approved","Yes") -> 4926004
B42: Grand Total | C42: 18455015
A45: KPI Q8- Average Loan Amount.
B47: Average of Loan_Amount
B48: 19426.332 | C48: =GETPIVOTDATA("Loan_Amount",$B$47) -> 19426.332
A52: KPI Q9- Average Applicant Income
B55: Average of Applicant_Income
B56: 10327.543 | C56: =GETPIVOTDATA("Applicant_Income",$B$55) -> 10327.543
A59: KPI Q10- Average DTI Ratio
B61: Average of DTI_Ratio
B62: 0.34743158 | C62: =GETPIVOTDATA("DTI_Ratio",$B$61) -> 0.34743158
A65: KPI Q11- DTI High-Risk Applicants %
B68: Row Labels | C68: Count of DTI RISK LEVEL
B69: High Risk | C69: 153 | D69: =GETPIVOTDATA("DTI RISK LEVEL",$B$68,"DTI RISK LEVEL","High Risk") -> 153 | F69: =GETPIVOTDATA("DTI RISK LEVEL",$B$68,"DTI RISK LEVEL","High Risk")/GETPIVOTDATA("DTI RISK LEVEL",$B$68) -> 0.16105263
B70: Low Risk | C70: 372 | D70: =GETPIVOTDATA("DTI RISK LEVEL",$B$68,"DTI RISK LEVEL","Low Risk") -> 372 | F70: =GETPIVOTDATA("DTI RISK LEVEL",$B$68,"DTI RISK LEVEL","Low Risk")/GETPIVOTDATA("DTI RISK LEVEL",$B$68) -> 0.39157895
B71: medium Risk | C71: 249 | D71: =GETPIVOTDATA("DTI RISK LEVEL",$B$68,"DTI RISK LEVEL","medium Risk") -> 249 | F71: =GETPIVOTDATA("DTI RISK LEVEL",$B$68,"DTI RISK LEVEL","medium Risk")/GETPIVOTDATA("DTI RISK LEVEL",$B$68) -> 0.26210526
B72: Very High Risk | C72: 176 | D72: =GETPIVOTDATA("DTI RISK LEVEL",$B$68,"DTI RISK LEVEL","Very High Risk") -> 176 | F72: =GETPIVOTDATA("DTI RISK LEVEL",$B$68,"DTI RISK LEVEL","Very High Risk")/GETPIVOTDATA("DTI RISK LEVEL",$B$68) -> 0.18526316
B73: Grand Total | C73: 950 | D73: =GETPIVOTDATA("DTI RISK LEVEL",$B$68)/950 -> 1 | F73: =D73 -> 1
A76: KPI Q12 - Low Credit Score %
B78: Row Labels | C78: Count of Credit Categorical
B79: fair | C79: 320 | D79: =GETPIVOTDATA("Credit Categorical",$B$78,"Credit Categorical","fair") -> 320 | F79: =GETPIVOTDATA("Credit Categorical",$B$78,"Credit Categorical","fair")/GETPIVOTDATA("Credit Categorical",$B$78) -> 0.33684211
B80: Good | C80: 273 | D80: =GETPIVOTDATA("Credit Categorical",$B$78,"Credit Categorical","Good") -> 273 | F80: =GETPIVOTDATA("Credit Categorical",$B$78,"Credit Categorical","Good")/GETPIVOTDATA("Credit Categorical",$B$78) -> 0.28736842
...

Sheet Dashboard
A1: LOAN APPROVAL DASHBOARD
A5: Total Applications | F5: Approved Rate VS Rejection Rate | M5: Total loan Amount Applied | R5: Average Loan Amount | W5: Average Applicant Income
A8: =GETPIVOTDATA("Applicant_ID",'Pivot table'!$B$3) -> 950 | F8: ='Pivot table'!D18 -> 1 | M8: ='Pivot table'!C32 -> 18455015 | R8: ='Pivot table'!C48 -> 19426.332 | W8: ='Pivot table'!C56 -> 10327.543
A10: Average DTI Ratio | F10: DTI High-Risk Applicants %
A13: ='Pivot table'!C62 -> 0.34743158 | F13: ='Pivot table'!F73 -> 1
